[2024-03-05 11:48:14,800] [MainThread:4345544000] [parallel_CPCES:82] [views:conformant_probabilistic_CPCES_by_hitting_set] [ERROR]- save error for TASK
Traceback (most recent call last):
  File "/Library/Python/3.8/site-packages/django/db/backends/utils.py", line 84, in _execute
    return self.cursor.execute(sql, params)
  File "/Library/Python/3.8/site-packages/django/db/backends/sqlite3/base.py", line 423, in execute
    return Database.Cursor.execute(self, query, params)
sqlite3.OperationalError: no such table: pCPCES_task

The above exception was the direct cause of the following exception:

Traceback (most recent call last):
  File "views.py", line 80, in conformant_probabilistic_CPCES_by_hitting_set
    planning_task.save()
  File "/Library/Python/3.8/site-packages/django/db/models/base.py", line 726, in save
    self.save_base(using=using, force_insert=force_insert,
  File "/Library/Python/3.8/site-packages/django/db/models/base.py", line 763, in save_base
    updated = self._save_table(
  File "/Library/Python/3.8/site-packages/django/db/models/base.py", line 868, in _save_table
    results = self._do_insert(cls._base_manager, using, fields, returning_fields, raw)
  File "/Library/Python/3.8/site-packages/django/db/models/base.py", line 906, in _do_insert
    return manager._insert(
  File "/Library/Python/3.8/site-packages/django/db/models/manager.py", line 85, in manager_method
    return getattr(self.get_queryset(), name)(*args, **kwargs)
  File "/Library/Python/3.8/site-packages/django/db/models/query.py", line 1270, in _insert
    return query.get_compiler(using=using).execute_sql(returning_fields)
  File "/Library/Python/3.8/site-packages/django/db/models/sql/compiler.py", line 1416, in execute_sql
    cursor.execute(sql, params)
  File "/Library/Python/3.8/site-packages/django/db/backends/utils.py", line 98, in execute
    return super().execute(sql, params)
  File "/Library/Python/3.8/site-packages/django/db/backends/utils.py", line 66, in execute
    return self._execute_with_wrappers(sql, params, many=False, executor=self._execute)
  File "/Library/Python/3.8/site-packages/django/db/backends/utils.py", line 75, in _execute_with_wrappers
    return executor(sql, params, many, context)
  File "/Library/Python/3.8/site-packages/django/db/backends/utils.py", line 84, in _execute
    return self.cursor.execute(sql, params)
  File "/Library/Python/3.8/site-packages/django/db/utils.py", line 90, in __exit__
    raise dj_exc_value.with_traceback(traceback) from exc_value
  File "/Library/Python/3.8/site-packages/django/db/backends/utils.py", line 84, in _execute
    return self.cursor.execute(sql, params)
  File "/Library/Python/3.8/site-packages/django/db/backends/sqlite3/base.py", line 423, in execute
    return Database.Cursor.execute(self, query, params)
django.db.utils.OperationalError: no such table: pCPCES_task
[2024-03-05 12:03:37,529] [MainThread:4375608640] [parallel_CPCES:82] [views:conformant_probabilistic_CPCES_by_hitting_set] [ERROR]- save error for TASK
Traceback (most recent call last):
  File "/Library/Python/3.8/site-packages/django/db/backends/utils.py", line 84, in _execute
    return self.cursor.execute(sql, params)
  File "/Library/Python/3.8/site-packages/django/db/backends/sqlite3/base.py", line 423, in execute
    return Database.Cursor.execute(self, query, params)
sqlite3.OperationalError: no such table: pCPCES_task

The above exception was the direct cause of the following exception:

Traceback (most recent call last):
  File "views.py", line 80, in conformant_probabilistic_CPCES_by_hitting_set
    planning_task.save()
  File "/Library/Python/3.8/site-packages/django/db/models/base.py", line 726, in save
    self.save_base(using=using, force_insert=force_insert,
  File "/Library/Python/3.8/site-packages/django/db/models/base.py", line 763, in save_base
    updated = self._save_table(
  File "/Library/Python/3.8/site-packages/django/db/models/base.py", line 868, in _save_table
    results = self._do_insert(cls._base_manager, using, fields, returning_fields, raw)
  File "/Library/Python/3.8/site-packages/django/db/models/base.py", line 906, in _do_insert
    return manager._insert(
  File "/Library/Python/3.8/site-packages/django/db/models/manager.py", line 85, in manager_method
    return getattr(self.get_queryset(), name)(*args, **kwargs)
  File "/Library/Python/3.8/site-packages/django/db/models/query.py", line 1270, in _insert
    return query.get_compiler(using=using).execute_sql(returning_fields)
  File "/Library/Python/3.8/site-packages/django/db/models/sql/compiler.py", line 1416, in execute_sql
    cursor.execute(sql, params)
  File "/Library/Python/3.8/site-packages/django/db/backends/utils.py", line 98, in execute
    return super().execute(sql, params)
  File "/Library/Python/3.8/site-packages/django/db/backends/utils.py", line 66, in execute
    return self._execute_with_wrappers(sql, params, many=False, executor=self._execute)
  File "/Library/Python/3.8/site-packages/django/db/backends/utils.py", line 75, in _execute_with_wrappers
    return executor(sql, params, many, context)
  File "/Library/Python/3.8/site-packages/django/db/backends/utils.py", line 84, in _execute
    return self.cursor.execute(sql, params)
  File "/Library/Python/3.8/site-packages/django/db/utils.py", line 90, in __exit__
    raise dj_exc_value.with_traceback(traceback) from exc_value
  File "/Library/Python/3.8/site-packages/django/db/backends/utils.py", line 84, in _execute
    return self.cursor.execute(sql, params)
  File "/Library/Python/3.8/site-packages/django/db/backends/sqlite3/base.py", line 423, in execute
    return Database.Cursor.execute(self, query, params)
django.db.utils.OperationalError: no such table: pCPCES_task
[2024-03-05 12:04:20,142] [MainThread:4308630848] [parallel_CPCES:82] [views:conformant_probabilistic_CPCES_by_hitting_set] [ERROR]- save error for TASK
Traceback (most recent call last):
  File "/Library/Python/3.8/site-packages/django/db/backends/utils.py", line 84, in _execute
    return self.cursor.execute(sql, params)
  File "/Library/Python/3.8/site-packages/django/db/backends/sqlite3/base.py", line 423, in execute
    return Database.Cursor.execute(self, query, params)
sqlite3.OperationalError: no such table: pCPCES_task

The above exception was the direct cause of the following exception:

Traceback (most recent call last):
  File "views.py", line 80, in conformant_probabilistic_CPCES_by_hitting_set
    planning_task.save()
  File "/Library/Python/3.8/site-packages/django/db/models/base.py", line 726, in save
    self.save_base(using=using, force_insert=force_insert,
  File "/Library/Python/3.8/site-packages/django/db/models/base.py", line 763, in save_base
    updated = self._save_table(
  File "/Library/Python/3.8/site-packages/django/db/models/base.py", line 868, in _save_table
    results = self._do_insert(cls._base_manager, using, fields, returning_fields, raw)
  File "/Library/Python/3.8/site-packages/django/db/models/base.py", line 906, in _do_insert
    return manager._insert(
  File "/Library/Python/3.8/site-packages/django/db/models/manager.py", line 85, in manager_method
    return getattr(self.get_queryset(), name)(*args, **kwargs)
  File "/Library/Python/3.8/site-packages/django/db/models/query.py", line 1270, in _insert
    return query.get_compiler(using=using).execute_sql(returning_fields)
  File "/Library/Python/3.8/site-packages/django/db/models/sql/compiler.py", line 1416, in execute_sql
    cursor.execute(sql, params)
  File "/Library/Python/3.8/site-packages/django/db/backends/utils.py", line 98, in execute
    return super().execute(sql, params)
  File "/Library/Python/3.8/site-packages/django/db/backends/utils.py", line 66, in execute
    return self._execute_with_wrappers(sql, params, many=False, executor=self._execute)
  File "/Library/Python/3.8/site-packages/django/db/backends/utils.py", line 75, in _execute_with_wrappers
    return executor(sql, params, many, context)
  File "/Library/Python/3.8/site-packages/django/db/backends/utils.py", line 84, in _execute
    return self.cursor.execute(sql, params)
  File "/Library/Python/3.8/site-packages/django/db/utils.py", line 90, in __exit__
    raise dj_exc_value.with_traceback(traceback) from exc_value
  File "/Library/Python/3.8/site-packages/django/db/backends/utils.py", line 84, in _execute
    return self.cursor.execute(sql, params)
  File "/Library/Python/3.8/site-packages/django/db/backends/sqlite3/base.py", line 423, in execute
    return Database.Cursor.execute(self, query, params)
django.db.utils.OperationalError: no such table: pCPCES_task
[2024-03-05 12:05:16,702] [MainThread:4342709568] [parallel_CPCES:82] [views:conformant_probabilistic_CPCES_by_hitting_set] [ERROR]- save error for TASK
Traceback (most recent call last):
  File "/Library/Python/3.8/site-packages/django/db/backends/utils.py", line 84, in _execute
    return self.cursor.execute(sql, params)
  File "/Library/Python/3.8/site-packages/django/db/backends/sqlite3/base.py", line 423, in execute
    return Database.Cursor.execute(self, query, params)
sqlite3.OperationalError: no such table: pCPCES_task

The above exception was the direct cause of the following exception:

Traceback (most recent call last):
  File "views.py", line 80, in conformant_probabilistic_CPCES_by_hitting_set
    planning_task.save()
  File "/Library/Python/3.8/site-packages/django/db/models/base.py", line 726, in save
    self.save_base(using=using, force_insert=force_insert,
  File "/Library/Python/3.8/site-packages/django/db/models/base.py", line 763, in save_base
    updated = self._save_table(
  File "/Library/Python/3.8/site-packages/django/db/models/base.py", line 868, in _save_table
    results = self._do_insert(cls._base_manager, using, fields, returning_fields, raw)
  File "/Library/Python/3.8/site-packages/django/db/models/base.py", line 906, in _do_insert
    return manager._insert(
  File "/Library/Python/3.8/site-packages/django/db/models/manager.py", line 85, in manager_method
    return getattr(self.get_queryset(), name)(*args, **kwargs)
  File "/Library/Python/3.8/site-packages/django/db/models/query.py", line 1270, in _insert
    return query.get_compiler(using=using).execute_sql(returning_fields)
  File "/Library/Python/3.8/site-packages/django/db/models/sql/compiler.py", line 1416, in execute_sql
    cursor.execute(sql, params)
  File "/Library/Python/3.8/site-packages/django/db/backends/utils.py", line 98, in execute
    return super().execute(sql, params)
  File "/Library/Python/3.8/site-packages/django/db/backends/utils.py", line 66, in execute
    return self._execute_with_wrappers(sql, params, many=False, executor=self._execute)
  File "/Library/Python/3.8/site-packages/django/db/backends/utils.py", line 75, in _execute_with_wrappers
    return executor(sql, params, many, context)
  File "/Library/Python/3.8/site-packages/django/db/backends/utils.py", line 84, in _execute
    return self.cursor.execute(sql, params)
  File "/Library/Python/3.8/site-packages/django/db/utils.py", line 90, in __exit__
    raise dj_exc_value.with_traceback(traceback) from exc_value
  File "/Library/Python/3.8/site-packages/django/db/backends/utils.py", line 84, in _execute
    return self.cursor.execute(sql, params)
  File "/Library/Python/3.8/site-packages/django/db/backends/sqlite3/base.py", line 423, in execute
    return Database.Cursor.execute(self, query, params)
django.db.utils.OperationalError: no such table: pCPCES_task
[2024-03-05 12:06:26,342] [MainThread:4376902976] [parallel_CPCES:82] [views:conformant_probabilistic_CPCES_by_hitting_set] [ERROR]- save error for TASK
Traceback (most recent call last):
  File "/Library/Python/3.8/site-packages/django/db/backends/utils.py", line 84, in _execute
    return self.cursor.execute(sql, params)
  File "/Library/Python/3.8/site-packages/django/db/backends/sqlite3/base.py", line 423, in execute
    return Database.Cursor.execute(self, query, params)
sqlite3.OperationalError: no such table: pCPCES_task

The above exception was the direct cause of the following exception:

Traceback (most recent call last):
  File "views.py", line 80, in conformant_probabilistic_CPCES_by_hitting_set
    planning_task.save()
  File "/Library/Python/3.8/site-packages/django/db/models/base.py", line 726, in save
    self.save_base(using=using, force_insert=force_insert,
  File "/Library/Python/3.8/site-packages/django/db/models/base.py", line 763, in save_base
    updated = self._save_table(
  File "/Library/Python/3.8/site-packages/django/db/models/base.py", line 868, in _save_table
    results = self._do_insert(cls._base_manager, using, fields, returning_fields, raw)
  File "/Library/Python/3.8/site-packages/django/db/models/base.py", line 906, in _do_insert
    return manager._insert(
  File "/Library/Python/3.8/site-packages/django/db/models/manager.py", line 85, in manager_method
    return getattr(self.get_queryset(), name)(*args, **kwargs)
  File "/Library/Python/3.8/site-packages/django/db/models/query.py", line 1270, in _insert
    return query.get_compiler(using=using).execute_sql(returning_fields)
  File "/Library/Python/3.8/site-packages/django/db/models/sql/compiler.py", line 1416, in execute_sql
    cursor.execute(sql, params)
  File "/Library/Python/3.8/site-packages/django/db/backends/utils.py", line 98, in execute
    return super().execute(sql, params)
  File "/Library/Python/3.8/site-packages/django/db/backends/utils.py", line 66, in execute
    return self._execute_with_wrappers(sql, params, many=False, executor=self._execute)
  File "/Library/Python/3.8/site-packages/django/db/backends/utils.py", line 75, in _execute_with_wrappers
    return executor(sql, params, many, context)
  File "/Library/Python/3.8/site-packages/django/db/backends/utils.py", line 84, in _execute
    return self.cursor.execute(sql, params)
  File "/Library/Python/3.8/site-packages/django/db/utils.py", line 90, in __exit__
    raise dj_exc_value.with_traceback(traceback) from exc_value
  File "/Library/Python/3.8/site-packages/django/db/backends/utils.py", line 84, in _execute
    return self.cursor.execute(sql, params)
  File "/Library/Python/3.8/site-packages/django/db/backends/sqlite3/base.py", line 423, in execute
    return Database.Cursor.execute(self, query, params)
django.db.utils.OperationalError: no such table: pCPCES_task
[2024-03-05 12:08:58,836] [MainThread:4381932864] [parallel_CPCES:82] [views:conformant_probabilistic_CPCES_by_hitting_set] [ERROR]- save error for TASK
Traceback (most recent call last):
  File "/Library/Python/3.8/site-packages/django/db/backends/utils.py", line 84, in _execute
    return self.cursor.execute(sql, params)
  File "/Library/Python/3.8/site-packages/django/db/backends/sqlite3/base.py", line 423, in execute
    return Database.Cursor.execute(self, query, params)
sqlite3.OperationalError: no such table: pCPCES_task

The above exception was the direct cause of the following exception:

Traceback (most recent call last):
  File "views.py", line 80, in conformant_probabilistic_CPCES_by_hitting_set
    planning_task.save()
  File "/Library/Python/3.8/site-packages/django/db/models/base.py", line 726, in save
    self.save_base(using=using, force_insert=force_insert,
  File "/Library/Python/3.8/site-packages/django/db/models/base.py", line 763, in save_base
    updated = self._save_table(
  File "/Library/Python/3.8/site-packages/django/db/models/base.py", line 868, in _save_table
    results = self._do_insert(cls._base_manager, using, fields, returning_fields, raw)
  File "/Library/Python/3.8/site-packages/django/db/models/base.py", line 906, in _do_insert
    return manager._insert(
  File "/Library/Python/3.8/site-packages/django/db/models/manager.py", line 85, in manager_method
    return getattr(self.get_queryset(), name)(*args, **kwargs)
  File "/Library/Python/3.8/site-packages/django/db/models/query.py", line 1270, in _insert
    return query.get_compiler(using=using).execute_sql(returning_fields)
  File "/Library/Python/3.8/site-packages/django/db/models/sql/compiler.py", line 1416, in execute_sql
    cursor.execute(sql, params)
  File "/Library/Python/3.8/site-packages/django/db/backends/utils.py", line 98, in execute
    return super().execute(sql, params)
  File "/Library/Python/3.8/site-packages/django/db/backends/utils.py", line 66, in execute
    return self._execute_with_wrappers(sql, params, many=False, executor=self._execute)
  File "/Library/Python/3.8/site-packages/django/db/backends/utils.py", line 75, in _execute_with_wrappers
    return executor(sql, params, many, context)
  File "/Library/Python/3.8/site-packages/django/db/backends/utils.py", line 84, in _execute
    return self.cursor.execute(sql, params)
  File "/Library/Python/3.8/site-packages/django/db/utils.py", line 90, in __exit__
    raise dj_exc_value.with_traceback(traceback) from exc_value
  File "/Library/Python/3.8/site-packages/django/db/backends/utils.py", line 84, in _execute
    return self.cursor.execute(sql, params)
  File "/Library/Python/3.8/site-packages/django/db/backends/sqlite3/base.py", line 423, in execute
    return Database.Cursor.execute(self, query, params)
django.db.utils.OperationalError: no such table: pCPCES_task
[2024-03-05 12:09:11,066] [MainThread:4372282688] [parallel_CPCES:82] [views:conformant_probabilistic_CPCES_by_hitting_set] [ERROR]- save error for TASK
Traceback (most recent call last):
  File "/Library/Python/3.8/site-packages/django/db/backends/utils.py", line 84, in _execute
    return self.cursor.execute(sql, params)
  File "/Library/Python/3.8/site-packages/django/db/backends/sqlite3/base.py", line 423, in execute
    return Database.Cursor.execute(self, query, params)
sqlite3.OperationalError: no such table: pCPCES_task

The above exception was the direct cause of the following exception:

Traceback (most recent call last):
  File "views.py", line 80, in conformant_probabilistic_CPCES_by_hitting_set
    planning_task.save()
  File "/Library/Python/3.8/site-packages/django/db/models/base.py", line 726, in save
    self.save_base(using=using, force_insert=force_insert,
  File "/Library/Python/3.8/site-packages/django/db/models/base.py", line 763, in save_base
    updated = self._save_table(
  File "/Library/Python/3.8/site-packages/django/db/models/base.py", line 868, in _save_table
    results = self._do_insert(cls._base_manager, using, fields, returning_fields, raw)
  File "/Library/Python/3.8/site-packages/django/db/models/base.py", line 906, in _do_insert
    return manager._insert(
  File "/Library/Python/3.8/site-packages/django/db/models/manager.py", line 85, in manager_method
    return getattr(self.get_queryset(), name)(*args, **kwargs)
  File "/Library/Python/3.8/site-packages/django/db/models/query.py", line 1270, in _insert
    return query.get_compiler(using=using).execute_sql(returning_fields)
  File "/Library/Python/3.8/site-packages/django/db/models/sql/compiler.py", line 1416, in execute_sql
    cursor.execute(sql, params)
  File "/Library/Python/3.8/site-packages/django/db/backends/utils.py", line 98, in execute
    return super().execute(sql, params)
  File "/Library/Python/3.8/site-packages/django/db/backends/utils.py", line 66, in execute
    return self._execute_with_wrappers(sql, params, many=False, executor=self._execute)
  File "/Library/Python/3.8/site-packages/django/db/backends/utils.py", line 75, in _execute_with_wrappers
    return executor(sql, params, many, context)
  File "/Library/Python/3.8/site-packages/django/db/backends/utils.py", line 84, in _execute
    return self.cursor.execute(sql, params)
  File "/Library/Python/3.8/site-packages/django/db/utils.py", line 90, in __exit__
    raise dj_exc_value.with_traceback(traceback) from exc_value
  File "/Library/Python/3.8/site-packages/django/db/backends/utils.py", line 84, in _execute
    return self.cursor.execute(sql, params)
  File "/Library/Python/3.8/site-packages/django/db/backends/sqlite3/base.py", line 423, in execute
    return Database.Cursor.execute(self, query, params)
django.db.utils.OperationalError: no such table: pCPCES_task
[2024-03-05 12:13:41,931] [MainThread:4375739712] [parallel_CPCES:82] [views:conformant_probabilistic_CPCES_by_hitting_set] [ERROR]- save error for TASK
Traceback (most recent call last):
  File "/Library/Python/3.8/site-packages/django/db/backends/utils.py", line 84, in _execute
    return self.cursor.execute(sql, params)
  File "/Library/Python/3.8/site-packages/django/db/backends/sqlite3/base.py", line 423, in execute
    return Database.Cursor.execute(self, query, params)
sqlite3.OperationalError: no such table: pCPCES_task

The above exception was the direct cause of the following exception:

Traceback (most recent call last):
  File "views.py", line 80, in conformant_probabilistic_CPCES_by_hitting_set
    planning_task.save()
  File "/Library/Python/3.8/site-packages/django/db/models/base.py", line 726, in save
    self.save_base(using=using, force_insert=force_insert,
  File "/Library/Python/3.8/site-packages/django/db/models/base.py", line 763, in save_base
    updated = self._save_table(
  File "/Library/Python/3.8/site-packages/django/db/models/base.py", line 868, in _save_table
    results = self._do_insert(cls._base_manager, using, fields, returning_fields, raw)
  File "/Library/Python/3.8/site-packages/django/db/models/base.py", line 906, in _do_insert
    return manager._insert(
  File "/Library/Python/3.8/site-packages/django/db/models/manager.py", line 85, in manager_method
    return getattr(self.get_queryset(), name)(*args, **kwargs)
  File "/Library/Python/3.8/site-packages/django/db/models/query.py", line 1270, in _insert
    return query.get_compiler(using=using).execute_sql(returning_fields)
  File "/Library/Python/3.8/site-packages/django/db/models/sql/compiler.py", line 1416, in execute_sql
    cursor.execute(sql, params)
  File "/Library/Python/3.8/site-packages/django/db/backends/utils.py", line 98, in execute
    return super().execute(sql, params)
  File "/Library/Python/3.8/site-packages/django/db/backends/utils.py", line 66, in execute
    return self._execute_with_wrappers(sql, params, many=False, executor=self._execute)
  File "/Library/Python/3.8/site-packages/django/db/backends/utils.py", line 75, in _execute_with_wrappers
    return executor(sql, params, many, context)
  File "/Library/Python/3.8/site-packages/django/db/backends/utils.py", line 84, in _execute
    return self.cursor.execute(sql, params)
  File "/Library/Python/3.8/site-packages/django/db/utils.py", line 90, in __exit__
    raise dj_exc_value.with_traceback(traceback) from exc_value
  File "/Library/Python/3.8/site-packages/django/db/backends/utils.py", line 84, in _execute
    return self.cursor.execute(sql, params)
  File "/Library/Python/3.8/site-packages/django/db/backends/sqlite3/base.py", line 423, in execute
    return Database.Cursor.execute(self, query, params)
django.db.utils.OperationalError: no such table: pCPCES_task
[2024-03-05 12:15:30,551] [MainThread:4346117440] [parallel_CPCES:82] [views:conformant_probabilistic_CPCES_by_hitting_set] [ERROR]- save error for TASK
Traceback (most recent call last):
  File "/Library/Python/3.8/site-packages/django/db/backends/utils.py", line 84, in _execute
    return self.cursor.execute(sql, params)
  File "/Library/Python/3.8/site-packages/django/db/backends/sqlite3/base.py", line 423, in execute
    return Database.Cursor.execute(self, query, params)
sqlite3.OperationalError: no such table: pCPCES_task

The above exception was the direct cause of the following exception:

Traceback (most recent call last):
  File "views.py", line 80, in conformant_probabilistic_CPCES_by_hitting_set
    planning_task.save()
  File "/Library/Python/3.8/site-packages/django/db/models/base.py", line 726, in save
    self.save_base(using=using, force_insert=force_insert,
  File "/Library/Python/3.8/site-packages/django/db/models/base.py", line 763, in save_base
    updated = self._save_table(
  File "/Library/Python/3.8/site-packages/django/db/models/base.py", line 868, in _save_table
    results = self._do_insert(cls._base_manager, using, fields, returning_fields, raw)
  File "/Library/Python/3.8/site-packages/django/db/models/base.py", line 906, in _do_insert
    return manager._insert(
  File "/Library/Python/3.8/site-packages/django/db/models/manager.py", line 85, in manager_method
    return getattr(self.get_queryset(), name)(*args, **kwargs)
  File "/Library/Python/3.8/site-packages/django/db/models/query.py", line 1270, in _insert
    return query.get_compiler(using=using).execute_sql(returning_fields)
  File "/Library/Python/3.8/site-packages/django/db/models/sql/compiler.py", line 1416, in execute_sql
    cursor.execute(sql, params)
  File "/Library/Python/3.8/site-packages/django/db/backends/utils.py", line 98, in execute
    return super().execute(sql, params)
  File "/Library/Python/3.8/site-packages/django/db/backends/utils.py", line 66, in execute
    return self._execute_with_wrappers(sql, params, many=False, executor=self._execute)
  File "/Library/Python/3.8/site-packages/django/db/backends/utils.py", line 75, in _execute_with_wrappers
    return executor(sql, params, many, context)
  File "/Library/Python/3.8/site-packages/django/db/backends/utils.py", line 84, in _execute
    return self.cursor.execute(sql, params)
  File "/Library/Python/3.8/site-packages/django/db/utils.py", line 90, in __exit__
    raise dj_exc_value.with_traceback(traceback) from exc_value
  File "/Library/Python/3.8/site-packages/django/db/backends/utils.py", line 84, in _execute
    return self.cursor.execute(sql, params)
  File "/Library/Python/3.8/site-packages/django/db/backends/sqlite3/base.py", line 423, in execute
    return Database.Cursor.execute(self, query, params)
django.db.utils.OperationalError: no such table: pCPCES_task
[2024-03-05 12:16:13,315] [MainThread:4335582528] [parallel_CPCES:82] [views:conformant_probabilistic_CPCES_by_hitting_set] [ERROR]- save error for TASK
Traceback (most recent call last):
  File "/Library/Python/3.8/site-packages/django/db/backends/utils.py", line 84, in _execute
    return self.cursor.execute(sql, params)
  File "/Library/Python/3.8/site-packages/django/db/backends/sqlite3/base.py", line 423, in execute
    return Database.Cursor.execute(self, query, params)
sqlite3.OperationalError: no such table: pCPCES_task

The above exception was the direct cause of the following exception:

Traceback (most recent call last):
  File "views.py", line 80, in conformant_probabilistic_CPCES_by_hitting_set
    planning_task.save()
  File "/Library/Python/3.8/site-packages/django/db/models/base.py", line 726, in save
    self.save_base(using=using, force_insert=force_insert,
  File "/Library/Python/3.8/site-packages/django/db/models/base.py", line 763, in save_base
    updated = self._save_table(
  File "/Library/Python/3.8/site-packages/django/db/models/base.py", line 868, in _save_table
    results = self._do_insert(cls._base_manager, using, fields, returning_fields, raw)
  File "/Library/Python/3.8/site-packages/django/db/models/base.py", line 906, in _do_insert
    return manager._insert(
  File "/Library/Python/3.8/site-packages/django/db/models/manager.py", line 85, in manager_method
    return getattr(self.get_queryset(), name)(*args, **kwargs)
  File "/Library/Python/3.8/site-packages/django/db/models/query.py", line 1270, in _insert
    return query.get_compiler(using=using).execute_sql(returning_fields)
  File "/Library/Python/3.8/site-packages/django/db/models/sql/compiler.py", line 1416, in execute_sql
    cursor.execute(sql, params)
  File "/Library/Python/3.8/site-packages/django/db/backends/utils.py", line 98, in execute
    return super().execute(sql, params)
  File "/Library/Python/3.8/site-packages/django/db/backends/utils.py", line 66, in execute
    return self._execute_with_wrappers(sql, params, many=False, executor=self._execute)
  File "/Library/Python/3.8/site-packages/django/db/backends/utils.py", line 75, in _execute_with_wrappers
    return executor(sql, params, many, context)
  File "/Library/Python/3.8/site-packages/django/db/backends/utils.py", line 84, in _execute
    return self.cursor.execute(sql, params)
  File "/Library/Python/3.8/site-packages/django/db/utils.py", line 90, in __exit__
    raise dj_exc_value.with_traceback(traceback) from exc_value
  File "/Library/Python/3.8/site-packages/django/db/backends/utils.py", line 84, in _execute
    return self.cursor.execute(sql, params)
  File "/Library/Python/3.8/site-packages/django/db/backends/sqlite3/base.py", line 423, in execute
    return Database.Cursor.execute(self, query, params)
django.db.utils.OperationalError: no such table: pCPCES_task
